# 线程的未捕获异常UncaughtException应该如何处理

## 为什么需要UncaughtExceptionHandler？

原因如下：

* 主线程可以轻松发现异常，子线程却不行

代码演示：主线程抛出异常，子线程不受影响

```java
package threadcoreknowledge.uncaughtexception;

/**
 * 单线程，抛出，处理，有异常堆栈
 * 多线程，子线程发生异常，主线程不受影响
 * @author mfh
 * @date 2020/5/3 19:43
 */
public class ExceptionInChildThread implements Runnable {
    public static void main(String[] args) {
        new Thread(new ExceptionInChildThread()).start();
        for (int i = 0; i < 1000; i++) {
            System.out.println(i);
        }
    }
    @Override
    public void run() {
        throw new RuntimeException();
    }
}

```

结果：

```java
0
1
2
3
4
......
    Exception in thread "Thread-0" java.lang.RuntimeException
	at threadcoreknowledge.uncaughtexception.ExceptionInChildThread.run(ExceptionInChildThread.java:18)
	at java.lang.Thread.run(Thread.java:748)
989
990
991
992
993
994
995
996
997
998
999
```

子线程打印出堆栈异常信息，但主线程继续执行，直到结束

* 子线程异常无法用传统方法捕获

第一种情况：不使用 try catch，子线程抛出异常，这看着挺正常的

```java
package threadcoreknowledge.uncaughtexception;

/**
 * 1.不加 try catch 抛出4个异常
 * 2.加了 try catch，期望捕获到第一个线程的异常，线程234不应该运行，希望看到打印 Caught Exception
 * 3.执行时发现，根本没有 Caught Exception，线程234依然运行并且抛出异常
 * 说明线程的异常不能用传统方法捕获
 * @author mfh
 * @date 2020/5/3 20:06
 */
public class CantCatchDirectly implements Runnable {
    public static void main(String... args) {
        new Thread(new CantCatchDirectly(), "Thread-1").start();
        new Thread(new CantCatchDirectly(), "Thread-1").start();
        new Thread(new CantCatchDirectly(), "Thread-1").start();
        new Thread(new CantCatchDirectly(), "Thread-1").start();
    }
    @Override
    public void run() {
        throw new RuntimeException();
    }
}
```

结果：

```java
Exception in thread "Thread-1" java.lang.RuntimeException
	at threadcoreknowledge.uncaughtexception.CantCatchDirectly.run(CantCatchDirectly.java:20)
	at java.lang.Thread.run(Thread.java:748)
Exception in thread "Thread-1" java.lang.RuntimeException
	at threadcoreknowledge.uncaughtexception.CantCatchDirectly.run(CantCatchDirectly.java:20)
	at java.lang.Thread.run(Thread.java:748)
Exception in thread "Thread-1" java.lang.RuntimeException
	at threadcoreknowledge.uncaughtexception.CantCatchDirectly.run(CantCatchDirectly.java:20)
	at java.lang.Thread.run(Thread.java:748)
Exception in thread "Thread-1" java.lang.RuntimeException
	at threadcoreknowledge.uncaughtexception.CantCatchDirectly.run(CantCatchDirectly.java:20)
	at java.lang.Thread.run(Thread.java:748)
```

第二种情况，加 try catch，期望捕获到第一个线程的异常，线程234不应该运行，希望看到打印 Caught Exception，但是**事与愿违**

```java
package threadcoreknowledge.uncaughtexception;

/**
 * 1.不加 try catch 抛出4个异常
 * 2.加了 try catch，期望捕获到第一个线程的异常，线程234不应该运行，希望看到打印 Caught Exception
 * 3.执行时发现，根本没有 Caught Exception，线程234依然运行并且抛出异常
 * 说明线程的异常不能用传统方法捕获
 * @author mfh
 * @date 2020/5/3 20:06
 */
public class CantCatchDirectly implements Runnable {
    public static void main(String... args) {
        try {
            new Thread(new CantCatchDirectly(), "Thread-1").start();
            new Thread(new CantCatchDirectly(), "Thread-1").start();
            new Thread(new CantCatchDirectly(), "Thread-1").start();
            new Thread(new CantCatchDirectly(), "Thread-1").start();
        } catch (Exception e) {
            System.out.println("Caught Exception.");
        }
    }
    @Override
    public void run() {
        throw new RuntimeException();
    }
}

```

代码如下：

```java
package threadcoreknowledge.uncaughtexception;

/**
 * 1.不加 try catch 抛出4个异常
 * 2.加了 try catch，期望捕获到第一个线程的异常，线程234不应该运行，希望看到打印 Caught Exception
 * 3.执行时发现，根本没有 Caught Exception，线程234依然运行并且抛出异常
 * 说明线程的异常不能用传统方法捕获
 * @author mfh
 * @date 2020/5/3 20:06
 */
public class CantCatchDirectly implements Runnable {
    public static void main(String... args) {
        try {
            new Thread(new CantCatchDirectly(), "Thread-1").start();
            new Thread(new CantCatchDirectly(), "Thread-1").start();
            new Thread(new CantCatchDirectly(), "Thread-1").start();
            new Thread(new CantCatchDirectly(), "Thread-1").start();
        } catch (Exception e) {
            System.out.println("Caught Exception.");
        }
    }
    @Override
    public void run() {
        throw new RuntimeException();
    }
}
```

结果：

```java
Exception in thread "Thread-1" Exception in thread "Thread-1" Exception in thread "Thread-1" Exception in thread "Thread-1" java.lang.RuntimeException
	at threadcoreknowledge.uncaughtexception.CantCatchDirectly.run(CantCatchDirectly.java:24)
	at java.lang.Thread.run(Thread.java:748)
java.lang.RuntimeException
	at threadcoreknowledge.uncaughtexception.CantCatchDirectly.run(CantCatchDirectly.java:24)
	at java.lang.Thread.run(Thread.java:748)
java.lang.RuntimeException
	at threadcoreknowledge.uncaughtexception.CantCatchDirectly.run(CantCatchDirectly.java:24)
	at java.lang.Thread.run(Thread.java:748)
java.lang.RuntimeException
	at threadcoreknowledge.uncaughtexception.CantCatchDirectly.run(CantCatchDirectly.java:24)
	at java.lang.Thread.run(Thread.java:748)
```

执行结果和没有加 try catch 时一样，`Caught Exception.`根本没有打印，或者说代码根本就没有执行到那里。

为什么会有这种情况呢？try catch 捕获的是当前线程的异常，也就是如果

```java
new Thread(new CantCatchDirectly(), "Thread-1").start();
new Thread(new CantCatchDirectly(), "Thread-1").start();
new Thread(new CantCatchDirectly(), "Thread-1").start();
new Thread(new CantCatchDirectly(), "Thread-1").start();
```

这四行代码发生了异常（比如线程重复启动），则 try catch 可以捕获到，但抛出异常的位置是子线程，所以主线程的 try catch 无能为力。

* 不能直接捕获的后果，提高健壮性

## 两种解决方案

### 第一种（不推荐）

手动在每个 run 方法里进行 try catch.

```java
package threadcoreknowledge.uncaughtexception;

/**
 * 1.不加 try catch 抛出4个异常
 * 2.加了 try catch，期望捕获到第一个线程的异常，线程234不应该运行，希望看到打印 Caught Exception
 * 3.执行时发现，根本没有 Caught Exception，线程234依然运行并且抛出异常
 * 说明线程的异常不能用传统方法捕获
 * @author mfh
 * @date 2020/5/3 20:06
 */
public class CantCatchDirectly implements Runnable {
    public static void main(String... args) {
        try {
            new Thread(new CantCatchDirectly(), "Thread-1").start();
            new Thread(new CantCatchDirectly(), "Thread-1").start();
            new Thread(new CantCatchDirectly(), "Thread-1").start();
            new Thread(new CantCatchDirectly(), "Thread-1").start();
        } catch (Exception e) {
            System.out.println("main Caught Exception.");
        }
    }
    @Override
    public void run() {
        try {
            throw new RuntimeException();
        } catch (RuntimeException e) {
            System.out.println("Caught Exception.");
        }
    }
}
```

结果：

```java
Caught Exception.
Caught Exception.
Caught Exception.
Caught Exception.
```

将`System.out.println("Caught Exception.");`换成更加健壮的修复逻辑或者报警机制，子线程的异常就能被正确的处理。但是这样会有一个弊端，就是要在每个 run 方法中都做这样的事情，这样做有点麻烦，所以推荐第二种方式。

### 第二种（UncaughtExceptionHandler）

利用 UncaughtExceptionHandler，检测由于未捕获异常而终止的情况，并且对此进行处理。

* UncaughtExceptionHandler 接口
* void uncaughtException(Thread t, Throwable e);
* 异常处理器的调用策略

源码：

```java
public void uncaughtException(Thread t, Throwable e) {
        if (parent != null) {
            parent.uncaughtException(t, e);
        } else {
            Thread.UncaughtExceptionHandler ueh =
                Thread.getDefaultUncaughtExceptionHandler();
            if (ueh != null) {
                ueh.uncaughtException(t, e);
            } else if (!(e instanceof ThreadDeath)) {
                System.err.print("Exception in thread \""
                                 + t.getName() + "\" ");
                e.printStackTrace(System.err);
            }
        }
   
```

* 自己实现
  * 给程序**统一**设置（推荐）
  * 给每个线程**单独**设置
    * 每个线程都有独立的异常处理器，在业务逻辑比较复杂的场景，可以使用这样的方法
  * 给**线程池**设置

  这里着重介绍第一种设置方式，代码如下：

  ```java
  package threadcoreknowledge.uncaughtexception.bestpractice;
  
  import java.util.logging.Level;
  import java.util.logging.Logger;
  
  /**
   * 自定义的异常处理器
   * @author mfh
   * @date 2020/5/3 20:44
   */
  public class MyUncaughtExceptionHandler implements Thread.UncaughtExceptionHandler {
      private String name;
  
      public MyUncaughtExceptionHandler(String name) {
          this.name = name;
      }
  
      @Override
      public void uncaughtException(Thread t, Throwable e) {
          Logger logger = Logger.getAnonymousLogger();
          logger.log(Level.WARNING, "线程异常，终止了：" + t.getName() + ", 异常信息：" + e);
          System.out.println(this.name + "捕获了异常：" + t.getName() + " 发生的异常");
      }
  }
  ```

  ```java
  package threadcoreknowledge.uncaughtexception.bestpractice;
  
  /**
   * 使用自定义异常处理器处理子线程异常
   * @author mfh
   * @date 2020/5/3 20:47
   */
  public class UseOwnUncaughtExceptionHandler implements Runnable {
      public static void main(String... args) throws InterruptedException {
          Thread.setDefaultUncaughtExceptionHandler(new MyUncaughtExceptionHandler("自定义异常捕获器"));
          new Thread(new UseOwnUncaughtExceptionHandler(), "Thread-1").start();
          Thread.sleep(100);
          new Thread(new UseOwnUncaughtExceptionHandler(), "Thread-1").start();
          Thread.sleep(100);
          new Thread(new UseOwnUncaughtExceptionHandler(), "Thread-1").start();
          Thread.sleep(100);
          new Thread(new UseOwnUncaughtExceptionHandler(), "Thread-1").start();
      }
  
      @Override
      public void run() {
          throw new RuntimeException();
      }
  }
  
  ```

  结果：

  ```java
  五月 03, 2020 8:49:36 下午 threadcoreknowledge.uncaughtexception.bestpractice.MyUncaughtExceptionHandler uncaughtException
  警告: 线程异常，终止了：Thread-1, 异常信息：java.lang.RuntimeException
  自定义异常捕获器捕获了异常：Thread-1 发生的异常
  五月 03, 2020 8:49:36 下午 threadcoreknowledge.uncaughtexception.bestpractice.MyUncaughtExceptionHandler uncaughtException
  警告: 线程异常，终止了：Thread-1, 异常信息：java.lang.RuntimeException
  自定义异常捕获器捕获了异常：Thread-1 发生的异常
  五月 03, 2020 8:49:36 下午 threadcoreknowledge.uncaughtexception.bestpractice.MyUncaughtExceptionHandler uncaughtException
  警告: 线程异常，终止了：Thread-1, 异常信息：java.lang.RuntimeException
  自定义异常捕获器捕获了异常：Thread-1 发生的异常
  五月 03, 2020 8:49:36 下午 threadcoreknowledge.uncaughtexception.bestpractice.MyUncaughtExceptionHandler uncaughtException
  警告: 线程异常，终止了：Thread-1, 异常信息：java.lang.RuntimeException
  自定义异常捕获器捕获了异常：Thread-1 发生的异常
  ```


## 面试

* java异常体系
* 如何处理全局异常？为什么要全局处理？不处理行不行
  * 使用自定义全局异常处理器，就是以上代码的处理方式。
  * 不处理肯定不行

* run 方法是否可以抛出异常？如果抛出异常，线程状态会怎么样？
  * 方法层面不能抛出异常，只能自己通过 try catch 处理，线程会终止运行
* 线程中如何处理某个未处理异常
  * 使用全局异常处理器（UncaughtExceptionHandler）

